2017-01-10 23:42:59 [boto] ERROR: Caught exception reading instance data
Traceback (most recent call last):
  File "/usr/lib/python2.7/dist-packages/boto/utils.py", line 210, in retry_url
    r = opener.open(req, timeout=timeout)
  File "/usr/lib/python2.7/urllib2.py", line 429, in open
    response = self._open(req, data)
  File "/usr/lib/python2.7/urllib2.py", line 447, in _open
    '_open', req)
  File "/usr/lib/python2.7/urllib2.py", line 407, in _call_chain
    result = func(*args)
  File "/usr/lib/python2.7/urllib2.py", line 1228, in http_open
    return self.do_open(httplib.HTTPConnection, req)
  File "/usr/lib/python2.7/urllib2.py", line 1198, in do_open
    raise URLError(err)
URLError: <urlopen error timed out>
2017-01-10 23:42:59 [boto] ERROR: Unable to read instance data, giving up
2017-01-10 23:45:48 [boto] ERROR: Caught exception reading instance data
Traceback (most recent call last):
  File "/usr/lib/python2.7/dist-packages/boto/utils.py", line 210, in retry_url
    r = opener.open(req, timeout=timeout)
  File "/usr/lib/python2.7/urllib2.py", line 429, in open
    response = self._open(req, data)
  File "/usr/lib/python2.7/urllib2.py", line 447, in _open
    '_open', req)
  File "/usr/lib/python2.7/urllib2.py", line 407, in _call_chain
    result = func(*args)
  File "/usr/lib/python2.7/urllib2.py", line 1228, in http_open
    return self.do_open(httplib.HTTPConnection, req)
  File "/usr/lib/python2.7/urllib2.py", line 1198, in do_open
    raise URLError(err)
URLError: <urlopen error timed out>
2017-01-10 23:45:48 [boto] ERROR: Unable to read instance data, giving up
2017-01-11 09:04:22 [scrapy] ERROR: Error downloading <GET http://www.almv.cn/183424/>: DNS lookup failed: address 'www.almv.cn' not found: [Errno -3] Temporary failure in name resolution.
